# 자바의정석

### 예외처리 (exception handling)
 - 프로그램이 실행중 어떤 원인에 의해서 오작동하거나 비정상적으로 종료되는 경우가 있다. 이러한 결과를 초래하는 원인을 프로그램 에러 또는 오류라고 한다.
 - 컴파일 에러 : 컴파일 시에 발생하는 에러 (소스코드에 대한 오타나 잘못된 구문 자료형 체크 등의 기본적인 검사를 수행하여 오류가 있는지 알려준다)
 - 런타임 에러 : 실행시에 발생하는 에러 (프로그램 실행도중 발생할 수 있는 경우)
 - 놀리적 에러 :  실행은 되지만 의도와 다르게 동작
 - 에러 (error) : 프로그램 코드에 의해서 수습될 수 없는 심각한 오류
 - 예외(exception) : 프로그램 코드에 의해서 수습될 수 있는 다소 미약한 오류

### 예외 클래스 계층구조
 - Exception 클래스들 : 사용자의 실수와 같은 외적인 요인에 의해 발생하는 예외
 - RuntimeException 클래스들 : 프로그래머의 실수로 발생하는 예외

### 예외 처리하기 try-catch문
 - 예외처리 (exception handling) : 프로그램 실행시 발생할 수 있는 예외에 대비한 코드를 작성
 - 프로그램의 비정상 종료를 막고 정상적인 실행상태를 유지하는 것
 - 흐름 : try 블럭내에서 예외가 발생한 경우
    - 발생한 예외와 일치하는 catch 블럭이 있는지 확인한다.
    - 일치하는 catch 블랙을 찾게 되면 catch블럭 내의 문장들을 수행하고 블럭을 빠져나간 후 문장을 계속수행한다.
    - 일치하는 catch블럭을 찾지 못하면 예외는 처리되지 못한다.
  
### 예외 발생과 catch 블럭
 - 예외가 발생하면 발생한 예외에 해당하는 클래스의 인스턴스가 만들어진다.
 - catch블럭을 차례로 타고 내려가면서 catch 블럭의 괄호()내에 선언된 참조변수의 종류와 생성된 예외클래스의 인스턴스에 instancdof 연산자를 이용해서 검사한다.
 - 검사결과가 true인 catch블럭을 찾게 되면 블럭에 있는 문장들을 수행한다.
 
### printStackTrace(), getMessage()
 - 예외가 발생했을때 생성되는 예외 클래스의 인스턴스에는 발생한 예외에 대한 정보가 담겨있다. printStackTrace(), getMessage() 통해  얻을수있다.
 - printStackTrace() : 예외 발생당시의 호출스택(Call stack)에 있었던 메서드의 정보와 예외 메시지를 화면에 출력한다.
 - getMessage() : 발생한 예외클래스의 인스턴스에 저장된 메시지를 얻을 수 있다.

### 멀티 catch 블럭
 - JDK1.7부터는 catch블럭을 `|`기호를 이용해서 하나의 catch 블럭으로 합칠수 있게됬다.
 - 멀티catch 블럭의 `|` 연결된 예외 클래스가 조상과 자손 관계에 있다면 컴파일 에러가 발생
 - 멀티catch는 하나의 catch 블럭으로 여러 예외를 처리 하기 떄문에, 멀티 catch블럭 내에서는 실제로 어떤 예외가 발생한 것인지 알수 없다.
 - 그리고 참조변수 e로 멀티 catch블럭에 |기호로 연결된 예외 클래스들의 공통 분모인 조상 예외 클래스에 선언된 멤버만 사용 할 수 있다.
```java
   try {
   
   } catch(ParentException | ChildException) {  //컴파일 에러
   
   }
```


### 예외 발생시키기
 - throw 키워드 : new Exception(); new를 이용해서 발생시키려는 예외 클래스의 객체를 만든다 그리고 throw로 던진다.
 - RuntimeException 클래스들 : unchecked 예외 컴파일러가 예외처리를 확인하지 않음
 - Exception 클래스들 : checked예외

### 메서드에 예외 선언하기
 - void method() throw Exception {} //이 메서드는 모든 종류의 예외가 발생할 가능성이 있다.

### finally 블럭
 - finally 블럭은 예외의 발생여부에 상관없이 실행되어야할 코드를 포함시킬 목적으로 사용된다.
 - try 블럭에서 return문이 실행되는 경우에도 finally블럭의 문장들이 먼저 실행된 후에 현재 실행 중인 메서드를 종료한다.

### 자동 자원 반환 try-with-resources문
 - jdk1.7 추가됨, 사용한 후에 꼭 닫아 줘야하는 것들이있다. 그래야 사용했던 자원이 반환된다.
 - try-with-resources문 try(객체생성) 객체를 생성하는 문장을넣으면, 이객체는 따로 close를 호출하지 않아도 try 블럭을 벗어나는 순간 자동적으로 close()가 된다.
 - 그 다음에 catch블럭 또는 finally 블럭이 수행된다.
 - try-with-resources 문에 의해 자동으로 객체의 close가 호출될 수 있으려면 AutoCloseable 이라는 인터페이스를 구현한 것이어야한다.
 - Throwable에는 억제된 예외와 관련된 다음과 같은 메서드가 정의되어 있다.
 - 그런데 자원을 닫는 과정에서 예외가 발생할 수도 있습니다. 이 때, try 블록 안에서 발생한 예외가 우선적으로 처리되고, 그 후에 자원을 닫을 때 발생한 예외가 처리됩니다. 이때 "Suppressed"라는 키워드를 사용해 자원을 닫을 때 발생한 예외를 명시할 수 있습니다.
 - public final synchronized void addSuppressed(Throwable exception) //억제된 예외를 추가
 - public final synchronized Throwable[] getSuppressed() // 억제된 예외를 반환